WARNING    - 2024-04-11 20:16:56,617 - client          : PyNaCl is not installed, voice will NOT be supported
INFO       - 2024-04-11 20:16:56,620 - client          : logging in using static token
INFO       - 2024-04-11 20:16:57,431 - gateway         : Shard ID None has connected to Gateway (Session ID: d7b1e9b7e6ef816427af7e23c07f5d17).
INFO       - 2024-04-11 20:30:45,508 - gateway         : Shard ID None has successfully RESUMED session d7b1e9b7e6ef816427af7e23c07f5d17.
INFO       - 2024-04-11 20:50:26,009 - gateway         : Shard ID None has successfully RESUMED session d7b1e9b7e6ef816427af7e23c07f5d17.
ERROR      - 2024-04-11 21:31:09,963 - client          : Ignoring exception in on_voice_state_update
Traceback (most recent call last):
  File "/home/thomaspi/ElGatoBot/.venv/lib/python3.11/site-packages/discord/client.py", line 441, in _run_event
    await coro(*args, **kwargs)
  File "/home/thomaspi/ElGatoBot/main.py", line 106, in Activity
    voicelog(before, after, member, path)
  File "/home/thomaspi/ElGatoBot/BotListen/voice.py", line 25, in voicelog
    return voiceactivity(member)
           ^^^^^^^^^^^^^^^^^^^^^
  File "/home/thomaspi/ElGatoBot/timer.py", line 20, in voiceactivity
    with open(f"logs/{name}/voiceactivity_dedupe.txt", 'r') as file:
         ^^^^^^^^^^^^^^^^^^^^^^^^^^^^^^^^^^^^^^^^^^^^^^^^^^
FileNotFoundError: [Errno 2] No such file or directory: 'logs/flipflop0903/voiceactivity_dedupe.txt'
ERROR      - 2024-04-11 21:36:01,873 - bot             : Ignoring exception in command None
discord.ext.commands.errors.CommandNotFound: Command "cleanlogs" is not found
ERROR      - 2024-04-11 21:36:30,170 - tree            : Ignoring exception in command 'voice_activity'
Traceback (most recent call last):
  File "/home/thomaspi/ElGatoBot/.venv/lib/python3.11/site-packages/discord/app_commands/commands.py", line 828, in _do_call
    return await self._callback(interaction, **params)  # type: ignore
           ^^^^^^^^^^^^^^^^^^^^^^^^^^^^^^^^^^^^^^^^^^^
  File "/home/thomaspi/ElGatoBot/main.py", line 131, in voice
    a.close()
    ^
UnboundLocalError: cannot access local variable 'a' where it is not associated with a value

The above exception was the direct cause of the following exception:

Traceback (most recent call last):
  File "/home/thomaspi/ElGatoBot/.venv/lib/python3.11/site-packages/discord/app_commands/tree.py", line 1248, in _call
    await command._invoke_with_namespace(interaction, namespace)
  File "/home/thomaspi/ElGatoBot/.venv/lib/python3.11/site-packages/discord/app_commands/commands.py", line 853, in _invoke_with_namespace
    return await self._do_call(interaction, transformed_values)
           ^^^^^^^^^^^^^^^^^^^^^^^^^^^^^^^^^^^^^^^^^^^^^^^^^^^^
  File "/home/thomaspi/ElGatoBot/.venv/lib/python3.11/site-packages/discord/app_commands/commands.py", line 846, in _do_call
    raise CommandInvokeError(self, e) from e
discord.app_commands.errors.CommandInvokeError: Command 'voice_activity' raised an exception: UnboundLocalError: cannot access local variable 'a' where it is not associated with a value
INFO       - 2024-04-11 21:54:43,871 - gateway         : Shard ID None has successfully RESUMED session d7b1e9b7e6ef816427af7e23c07f5d17.
